Workbook

Sheet Config
A1: fn_NAME | B1: ID | C1: Info | D1: ArduinoPin | E1: PATA_Pin | F1: Type | G1: ActiveLevel | H1: Description | I1: WireColor | K1: fn_NAME
A2: {=_xlfn._xlws.SORT(_xlfn.TOCOL(PhotoLayout!A1:AT170,3))} -> BTN01-left-blue_1 | B2: =IF(ISERR(SEARCH("_",A2,1)),LEFT(A2,SEARCH("-",A2)-1), LEFT(A2,SEARCH("_",A2)+1)) -> BTN01-left-blue_1 | D2: 33 | F2: DigitalIn | H2: Bal felső kék gomb | J2: 2 | K2: BTN01_left_blue
A3: BTN02-left-blue_2 | B3: =IF(ISERR(SEARCH("_",A3,1)),LEFT(A3,SEARCH("-",A3)-1), LEFT(A3,SEARCH("_",A3)+1)) -> BTN02-left-blue_2 | D3: 34 | F3: DigitalIn | H3: Bal felső kék gomb | J3: 2 | K3: BTN02_left_blue
A4: BTN03-left-blue_3 | B4: =IF(ISERR(SEARCH("_",A4,1)),LEFT(A4,SEARCH("-",A4)-1), LEFT(A4,SEARCH("_",A4)+1)) -> BTN03-left-blue_3 | D4: 35 | F4: DigitalIn | H4: Bal felső kék gomb | J4: 2 | K4: BTN03_left_blue
A5: BTN05-legrand | B5: =IF(ISERR(SEARCH("_",A5,1)),LEFT(A5,SEARCH("-",A5)-1), LEFT(A5,SEARCH("_",A5)+1)) -> BTN05 | D5: 28 | F5: DigitalIn | H5: Nagy fehér billenőkapcsoló | J5: 2 | K5: BTN05_legrand
A6: BTN06-legrand | B6: =IF(ISERR(SEARCH("_",A6,1)),LEFT(A6,SEARCH("-",A6)-1), LEFT(A6,SEARCH("_",A6)+1)) -> BTN06 | D6: 47 | F6: DigitalIn | H6: Nagy fehér billenőkapcsoló | J6: 5 | K6: BTN06_legrand
A7: BTN07-down-5_1 | B7: =IF(ISERR(SEARCH("_",A7,1)),LEFT(A7,SEARCH("-",A7)-1), LEFT(A7,SEARCH("_",A7)+1)) -> BTN07-down-5_1 | D7: 44 | F7: DigitalIn | H7: Lent 5 led | J7: 24 | K7: BTN07_down_5
A8: BTN08-down-5_2 | B8: =IF(ISERR(SEARCH("_",A8,1)),LEFT(A8,SEARCH("-",A8)-1), LEFT(A8,SEARCH("_",A8)+1)) -> BTN08-down-5_2 | D8: 27 | F8: DigitalIn | H8: Lent 5 led | J8: 25 | K8: BTN08_down_5
A9: BTN09-down-5_3 | B9: =IF(ISERR(SEARCH("_",A9,1)),LEFT(A9,SEARCH("-",A9)-1), LEFT(A9,SEARCH("_",A9)+1)) -> BTN09-down-5_3 | D9: 43 | F9: DigitalIn | H9: Lent 5 led | J9: 27 | K9: BTN09_down_5
A10: BTN10-down-5_4 | B10: =IF(ISERR(SEARCH("_",A10,1)),LEFT(A10,SEARCH("-",A10)-1), LEFT(A10,SEARCH("_",A10)+1)) -> BTN10-down-5_4 | D10: 26 | F10: DigitalIn | H10: Lent 5 led | J10: 29 | K10: BTN10_down_5
A11: BTN11-down-5_5 | B11: =IF(ISERR(SEARCH("_",A11,1)),LEFT(A11,SEARCH("-",A11)-1), LEFT(A11,SEARCH("_",A11)+1)) -> BTN11-down-5_5 | D11: 41 | F11: DigitalIn | H11: Lent 5 led | J11: 30 | K11: BTN11_down_5
A12: BTN12-right-color_1 | B12: =IF(ISERR(SEARCH("_",A12,1)),LEFT(A12,SEARCH("-",A12)-1), LEFT(A12,SEARCH("_",A12)+1)) -> BTN12-right-color_1 | D12: 30 | F12: DigitalIn | H12: Jobb fenn 3 gomb | J12: 31 | K12: BTN12_right_color
A13: BTN13-right-color_2 | B13: =IF(ISERR(SEARCH("_",A13,1)),LEFT(A13,SEARCH("-",A13)-1), LEFT(A13,SEARCH("_",A13)+1)) -> BTN13-right-color_2 | D13: 31 | F13: DigitalIn | H13: Jobb fenn 3 gomb | J13: 32 | K13: BTN13_right_color
A14: BTN14-right-color_3 | B14: =IF(ISERR(SEARCH("_",A14,1)),LEFT(A14,SEARCH("-",A14)-1), LEFT(A14,SEARCH("_",A14)+1)) -> BTN14-right-color_3 | D14: 32 | F14: DigitalIn | H14: Jobb fenn 3 gomb | J14: 33 | K14: BTN14_right_color
... A22: BUZ01-piezo | B22: =IF(ISERR(SEARCH("_",A22,1)),LEFT(A22,SEARCH("-",A22)-1), LEFT(A22,SEARCH("_",A22)+1)) -> BUZ01 | D22: 5 | F22: DigitalIn | H22: Hangszóró | J22: 44 | K22: BUZ01_piezo
A23: DIO01-ikarus_1 | B23: =IF(ISERR(SEARCH("_",A23,1)),LEFT(A23,SEARCH("-",A23)-1), LEFT(A23,SEARCH("_",A23)+1)) -> DIO01-ikarus_1 | C23: interrupt | D23: 2 | F23: DigitalOut | G23: HIGH | H23: Ikarus led lámpa | J23: 46 | K23: JOY01_menu
A24: DIO02-ikarus_2 | B24: =IF(ISERR(SEARCH("_",A24,1)),LEFT(A24,SEARCH("-",A24)-1), LEFT(A24,SEARCH("_",A24)+1)) -> DIO02-ikarus_2 | D24: 16 | F24: DigitalOut | G24: HIGH | H24: Ikarus led lámpa | J24: 47 | K24: LCD01_menu
A25: DIO03-ikarus_3 | B25: =IF(ISERR(SEARCH("_",A25,1)),LEFT(A25,SEARCH("-",A25)-1), LEFT(A25,SEARCH("_",A25)+1)) -> DIO03-ikarus_3 | D25: 17 | F25: DigitalOut | G25: HIGH | H25: Ikarus led lámpa | J25: 48 | K25: LED01_strip_bal3
A26: DIO04-ikarus_4 | B26: =IF(ISERR(SEARCH("_",A26,1)),LEFT(A26,SEARCH("-",A26)-1), LEFT(A26,SEARCH("_",A26)+1)) -> DIO04-ikarus_4 | C26: interrupt | D26: 3 | F26: DigitalOut | G26: HIGH | H26: Ikarus led lámpa | J26: 49 | K26: LED02_strip_around
A27: DIO05-ikarus_5 | B27: =IF(ISERR(SEARCH("_",A27,1)),LEFT(A27,SEARCH("-",A27)-1), LEFT(A27,SEARCH("_",A27)+1)) -> DIO05-ikarus_5 | C27: interrupt | D27: 18 | F27: DigitalOut | G27: HIGH | H27: Ikarus led lámpa | J27: 50 | K27: LED03_strip_down5
A28: DIO06-ikarus_6 | B28: =IF(ISERR(SEARCH("_",A28,1)),LEFT(A28,SEARCH("-",A28)-1), LEFT(A28,SEARCH("_",A28)+1)) -> DIO06-ikarus_6 | C28: interrupt | D28: 19 | F28: DigitalOut | G28: HIGH | H28: Ikarus led lámpa | J28: 51 | K28: LED04_strip_jobb3
A29: JOY01-menu | B29: =IF(ISERR(SEARCH("_",A29,1)),LEFT(A29,SEARCH("-",A29)-1), LEFT(A29,SEARCH("_",A29)+1)) -> JOY01 | D29: d53, x=a8, y=a9 | F29: AnalogIn | H29: Joystick gomb | J29: 52 | K29: LED05_strip_right5
A30: LCD01-menu | B30: =IF(ISERR(SEARCH("_",A30,1)),LEFT(A30,SEARCH("-",A30)-1), LEFT(A30,SEARCH("_",A30)+1)) -> LCD01 | C30: address: 0x27 | D30: i2c (20,21) | F30: DigitalIn | H30: LCD | J30: 53 | K30: POT1_top_red
A31: LED01-left-blue_1 | B31: =IF(ISERR(SEARCH("_",A31,1)),LEFT(A31,SEARCH("-",A31)-1), LEFT(A31,SEARCH("_",A31)+1)) -> LED01-left-blue_1 | C31: position 1-49 (50-70) | D31: 4 | F31: DigitalOut | G31: WS2812B | H31: RGB led csík | J31: i2c | K31: SW01_metal
A32: LED01-left-blue_2 | B32: =IF(ISERR(SEARCH("_",A32,1)),LEFT(A32,SEARCH("-",A32)-1), LEFT(A32,SEARCH("_",A32)+1)) -> LED01-left-blue_2 | D32: 4 | F32: DigitalOut | G32: WS2812B | H32: RGB led csík | K32: SW02_metal
A33: LED01-left-blue_3 | B33: =IF(ISERR(SEARCH("_",A33,1)),LEFT(A33,SEARCH("-",A33)-1), LEFT(A33,SEARCH("_",A33)+1)) -> LED01-left-blue_3 | D33: 4 | F33: DigitalOut | G33: WS2812B | H33: RGB led csík | K33: SW03_metal
A34: LED02-strip-around | B34: =IF(ISERR(SEARCH("_",A34,1)),LEFT(A34,SEARCH("-",A34)-1), LEFT(A34,SEARCH("_",A34)+1)) -> LED02 | C34: position 84-86 | D34: 4 | F34: DigitalOut | G34: WS2812B | H34: RGB led csík | K34: SW04_metal
A35: LED03-strip-down5_1 | B35: =IF(ISERR(SEARCH("_",A35,1)),LEFT(A35,SEARCH("-",A35)-1), LEFT(A35,SEARCH("_",A35)+1)) -> LED03-strip-down5_1 | D35: 4 | F35: DigitalOut | G35: WS2812B | H35: RGB led csík | K35: SW05_metal
A36: LED03-strip-down5_2 | B36: =IF(ISERR(SEARCH("_",A36,1)),LEFT(A36,SEARCH("-",A36)-1), LEFT(A36,SEARCH("_",A36)+1)) -> LED03-strip-down5_2 | D36: 4 | F36: DigitalOut | G36: WS2812B | H36: RGB led csík
A37: LED03-strip-down5_3 | B37: =IF(ISERR(SEARCH("_",A37,1)),LEFT(A37,SEARCH("-",A37)-1), LEFT(A37,SEARCH("_",A37)+1)) -> LED03-strip-down5_3 | D37: 4 | F37: DigitalOut | G37: WS2812B | H37: RGB led csík
A38: LED03-strip-down5_4 | B38: =IF(ISERR(SEARCH("_",A38,1)),LEFT(A38,SEARCH("-",A38)-1), LEFT(A38,SEARCH("_",A38)+1)) -> LED03-strip-down5_4 | D38: 4 | F38: DigitalOut | G38: WS2812B | H38: RGB led csík
A39: LED03-strip-down5_5 | B39: =IF(ISERR(SEARCH("_",A39,1)),LEFT(A39,SEARCH("-",A39)-1), LEFT(A39,SEARCH("_",A39)+1)) -> LED03-strip-down5_5 | D39: 4 | F39: DigitalOut | G39: WS2812B | H39: RGB led csík
A40: LED04-right-color_1 | B40: =IF(ISERR(SEARCH("_",A40,1)),LEFT(A40,SEARCH("-",A40)-1), LEFT(A40,SEARCH("_",A40)+1)) -> LED04-right-color_1 | C40: position 71-75 | D40: 4 | F40: DigitalOut | G40: WS2812B | H40: RGB led csík
A41: LED04-right-color_2 | B41: =IF(ISERR(SEARCH("_",A41,1)),LEFT(A41,SEARCH("-",A41)-1), LEFT(A41,SEARCH("_",A41)+1)) -> LED04-right-color_2 | D41: 4 | F41: DigitalOut | G41: WS2812B | H41: RGB led csík
A42: LED04-right-color_3 | B42: =IF(ISERR(SEARCH("_",A42,1)),LEFT(A42,SEARCH("-",A42)-1), LEFT(A42,SEARCH("_",A42)+1)) -> LED04-right-color_3 | D42: 4 | F42: DigitalOut | G42: WS2812B | H42: RGB led csík
A43: LED05-metal_1 | B43: =IF(ISERR(SEARCH("_",A43,1)),LEFT(A43,SEARCH("-",A43)-1), LEFT(A43,SEARCH("_",A43)+1)) -> LED05-metal_1 | C43: position 81-83 | D43: 4 | F43: DigitalOut | G43: WS2812B | H43: RGB led csík
A44: LED05-metal_2 | B44: =IF(ISERR(SEARCH("_",A44,1)),LEFT(A44,SEARCH("-",A44)-1), LEFT(A44,SEARCH("_",A44)+1)) -> LED05-metal_2 | D44: 4 | F44: DigitalOut | G44: WS2812B | H44: RGB led csík
A45: LED05-metal_3 | B45: =IF(ISERR(SEARCH("_",A45,1)),LEFT(A45,SEARCH("-",A45)-1), LEFT(A45,SEARCH("_",A45)+1)) -> LED05-metal_3 | D45: 4 | F45: DigitalOut | G45: WS2812B | H45: RGB led csík
A46: LED05-metal_4 | B46: =IF(ISERR(SEARCH("_",A46,1)),LEFT(A46,SEARCH("-",A46)-1), LEFT(A46,SEARCH("_",A46)+1)) -> LED05-metal_4 | D46: 4 | F46: DigitalOut | G46: WS2812B | H46: RGB led csík
A47: LED05-metal_5 | B47: =IF(ISERR(SEARCH("_",A47,1)),LEFT(A47,SEARCH("-",A47)-1), LEFT(A47,SEARCH("_",A47)+1)) -> LED05-metal_5 | D47: 4 | F47: DigitalOut | G47: WS2812B | H47: RGB led csík
...

Sheet GameLevel
A1: GameID | B1: MenuLevel (szint) | C1: Nehézség | D1: Time (sec) | E1: Hang jelzés | F1: Info
A2: Random | B2: 1 | C2: 1
A3: Random 2 | B3: 1 | C3: 1
A4: Cyclon | B4: 2 | C4: Belső nehézség Lépésidő LED-enként Elfogadott találati tartomány 1 50 ms közép ±4 LED, összesen +9 2 40 ms közép ±2 LED, összesen 5 3 40 ms közép ±2 LED, összesen 5 4 40 ms közép ±1 LED, összesen 3
A5: Cyclon | B5: 3 | C5: Belső nehézség Lépésidő LED-enként Elfogadott találati tartomány 1 40 ms közép ±4 LED, összesen +9 2 35 ms közép ±2 LED, összesen 5 3 30 ms közép ±2 LED, összesen 5 4 30 ms közép ±1 LED, összesen 3
A6: Cyclon | B6: 4 | C6: Belső nehézség Lépésidő LED-enként Elfogadott találati tartomány 1 50 ms közép ±2 LED, összesen 5 2 40 ms közép ±1 LED, összesen 3 3 35 ms közép +1 LED, összesen 2 4 20 ms közép +1 LED, összesen 2
A7: Cyclon | B7: 5 | C7: Belső nehézség Lépésidő LED-enként Elfogadott találati tartomány 1 40 ms közép ±2 LED, összesen 5 2 35 ms közép ±1 LED, összesen 3 3 30 ms közép +1 LED, összesen 2 4 20 ms csak a középső LED
A8: Sorrend (memory) | B8: 2 | C8: Zavarási mód: nincs | D8: nincs időlimit | F8: Memóriajáték, fehér leddel
A9: Sorrend (memory) | B9: 3 | C9: Zavarási mód: 4-6 LED RANDOM_SATURATED | D9: 3 másodperc / találat | E9: vége előtt 2 és 1 másodperccel | F9: Memóriajáték, fehér leddel
A10: Sorrend (memory) | B10: 4 | C10: Zavarási mód: 4-10 LED RANDOM_SATURATED | D10: 2 másodperc / találat | E10: vége előtt 1 és 0.5 másodperccel | F10: Memóriajáték, fehér leddel
A11: Sorrend (memory) | B11: 5 | C11: Zavarási mód: 8-10 LED RANDOM_SATURATED | D11: 1.2 másodperc / találat | E11: vége előtt 1 és 0.5 másodperccel | F11: Memóriajáték, fehér leddel
A12: Sima villogo | B12: 2 | C12: 1 | D12: 10 | F12: Random szín
A13: Kapcsolozar | B13: 3 | C13: inverz | D13: nincs időlimit
A14: Kapcsolozar | B14: 4 | C14: normal | D14: 2 sec | E14: vége előtt 1 és 0.5 másodperccel
A15: Párbaj | B15: 3 | D15: 2 sec | E15: vége előtt 1 és 0.5 másodperccel

Sheet PhotoLayout
AA5: POT1-top-red
AN7: BTN12-right-color_1
AP9: BTN15-push-right
C11: BTN01-left-blue_1 | E11: LED01-left-blue_1 | AK11: LED04-right-color_1
K13: LED02-strip-around
C17: BTN02-left-blue_2 | E17: LED01-left-blue_2 | AK17: LED04-right-color_2 | AN17: BTN13-right-color_2
C23: BTN03-left-blue_3 | E23: LED01-left-blue_3
AK25: LED04-right-color_3
AN29: BTN14-right-color_3
W65: BUZ01-piezo
AH71: LED05-metal_1 | AJ71: LED05-metal_2 | AL71: LED05-metal_3 | AN71: LED05-metal_4 | AQ71: LED05-metal_5
AH74: SW01-metal_1 | AJ74: SW02-metal_2 | AL74: SW03-metal_3 | AN74: SW04-metal_4 | AQ74: SW05-metal_5
O91: JOY01-menu
V93: LCD01-menu | AJ93: BTN16-ikarus_1 | AP93: BTN17-ikarus_2
AJ95: DIO01-ikarus_1 | AP95: DIO02-ikarus_2
AJ116: BTN18-ikarus_3 | AP116: BTN19-ikarus_4
AJ118: DIO03-ikarus_3 | AP118: DIO04-ikarus_4
U120: BTN05-legrand | Y120: BTN06-legrand
AJ138: BTN20-ikarus_5 | AP138: BTN21-ikarus_6
AJ140: DIO05-ikarus_5 | AP140: DIO06-ikarus_6
S147: LED03-strip-down5_1 | U147: LED03-strip-down5_2 | W147: LED03-strip-down5_3 | Y147: LED03-strip-down5_4 | AB147: LED03-strip-down5_5
S152: BTN07-down-5_1 | U152: BTN08-down-5_2 | W152: BTN09-down-5_3 | Y152: BTN10-down-5_4 | AA152: BTN11-down-5_5
AM156: SW06-infacol

Sheet GameControls
A1: GameId | B1: Level | C1: Action | D1: ControlId
A2: CYCLON | B2: 1-5 | C2: Start | D2: BTN15
A3: CYCLON | B3: 1-5 | C3: Action | D3: BTN15

Sheet PinMap_export
A1: =IF(Config!B1="","",Config!B1) -> ID | B1: =IF(Config!C1="","",Config!C1) -> Info | C1: =IF(Config!D1="","",Config!D1) -> ArduinoPin | D1: =IF(Config!F1="","",Config!F1) -> Type | E1: =IF(Config!G1="","",Config!G1) -> ActiveLevel
A2: =IF(Config!B2="","",Config!B2) -> BTN01-left-blue_1 | C2: =IF(Config!D2="","",Config!D2) -> 33 | D2: =IF(Config!F2="","",Config!F2) -> DigitalIn | E2: =IF(Config!G2="","",Config!G2)
A3: =IF(Config!B3="","",Config!B3) -> BTN02-left-blue_2 | C3: =IF(Config!D3="","",Config!D3) -> 34 | D3: =IF(Config!F3="","",Config!F3) -> DigitalIn | E3: =IF(Config!G3="","",Config!G3)
A4: =IF(Config!B4="","",Config!B4) -> BTN03-left-blue_3 | C4: =IF(Config!D4="","",Config!D4) -> 35 | D4: =IF(Config!F4="","",Config!F4) -> DigitalIn | E4: =IF(Config!G4="","",Config!G4)
A5: =IF(Config!B5="","",Config!B5) -> BTN05 | B5: =IF(Config!C5="","",Config!C5) | C5: =IF(Config!D5="","",Config!D5) -> 28 | D5: =IF(Config!F5="","",Config!F5) -> DigitalIn | E5: =IF(Config!G5="","",Config!G5)
A6: =IF(Config!B6="","",Config!B6) -> BTN06 | B6: =IF(Config!C6="","",Config!C6) | C6: =IF(Config!D6="","",Config!D6) -> 47 | D6: =IF(Config!F6="","",Config!F6) -> DigitalIn | E6: =IF(Config!G6="","",Config!G6)
A7: =IF(Config!B7="","",Config!B7) -> BTN07-down-5_1 | B7: =IF(Config!C7="","",Config!C7) | C7: =IF(Config!D7="","",Config!D7) -> 44 | D7: =IF(Config!F7="","",Config!F7) -> DigitalIn | E7: =IF(Config!G7="","",Config!G7)
A8: =IF(Config!B8="","",Config!B8) -> BTN08-down-5_2 | B8: =IF(Config!C8="","",Config!C8) | C8: =IF(Config!D8="","",Config!D8) -> 27 | D8: =IF(Config!F8="","",Config!F8) -> DigitalIn | E8: =IF(Config!G8="","",Config!G8)
A9: =IF(Config!B9="","",Config!B9) -> BTN09-down-5_3 | B9: =IF(Config!C9="","",Config!C9) | C9: =IF(Config!D9="","",Config!D9) -> 43 | D9: =IF(Config!F9="","",Config!F9) -> DigitalIn | E9: =IF(Config!G9="","",Config!G9)
A10: =IF(Config!B10="","",Config!B10) -> BTN10-down-5_4 | B10: =IF(Config!C10="","",Config!C10) | C10: =IF(Config!D10="","",Config!D10) -> 26 | D10: =IF(Config!F10="","",Config!F10) -> DigitalIn | E10: =IF(Config!G10="","",Config!G10)
A11: =IF(Config!B11="","",Config!B11) -> BTN11-down-5_5 | B11: =IF(Config!C11="","",Config!C11) | C11: =IF(Config!D11="","",Config!D11) -> 41 | D11: =IF(Config!F11="","",Config!F11) -> DigitalIn | E11: =IF(Config!G11="","",Config!G11)
A12: =IF(Config!B12="","",Config!B12) -> BTN12-right-color_1 | B12: =IF(Config!C12="","",Config!C12) | C12: =IF(Config!D12="","",Config!D12) -> 30 | D12: =IF(Config!F12="","",Config!F12) -> DigitalIn | E12: =IF(Config!G12="","",Config!G12)
A13: =IF(Config!B13="","",Config!B13) -> BTN13-right-color_2 | B13: =IF(Config!C13="","",Config!C13) | C13: =IF(Config!D13="","",Config!D13) -> 31 | D13: =IF(Config!F13="","",Config!F13) -> DigitalIn | E13: =IF(Config!G13="","",Config!G13)
A14: =IF(Config!B14="","",Config!B14) -> BTN14-right-color_3 | B14: =IF(Config!C14="","",Config!C14) | C14: =IF(Config!D14="","",Config!D14) -> 32 | D14: =IF(Config!F14="","",Config!F14) -> DigitalIn | E14: =IF(Config!G14="","",Config!G14)
A15: =IF(Config!B15="","",Config!B15) -> BTN15 | B15: =IF(Config!C15="","",Config!C15) | C15: =IF(Config!D15="","",Config!D15) -> 39 | D15: =IF(Config!F15="","",Config!F15) -> DigitalIn | E15: =IF(Config!G15="","",Config!G15)
A16: =IF(Config!B16="","",Config!B16) -> BTN16-ikarus_1 | B16: =IF(Config!C16="","",Config!C16) | C16: =IF(Config!D16="","",Config!D16) -> 52 | D16: =IF(Config!F16="","",Config!F16) -> DigitalIn | E16: =IF(Config!G16="","",Config!G16)
... A30: =IF(Config!B30="","",Config!B30) -> LCD01 | B30: =IF(Config!C30="","",Config!C30) -> address: 0x27 | C30: =IF(Config!D30="","",Config!D30) -> i2c (20,21) | D30: =IF(Config!F30="","",Config!F30) -> DigitalIn | E30: =IF(Config!G30="","",Config!G30)
A31: =IF(Config!B31="","",Config!B31) -> LED01-left-blue_1 | B31: 84 | C31: =IF(Config!D31="","",Config!D31) -> 4 | D31: =IF(Config!F31="","",Config!F31) -> DigitalOut | E31: =IF(Config!G31="","",Config!G31) -> WS2812B
A32: =IF(Config!B32="","",Config!B32) -> LED01-left-blue_2 | B32: 85 | C32: =IF(Config!D32="","",Config!D32) -> 4 | D32: =IF(Config!F32="","",Config!F32) -> DigitalOut | E32: =IF(Config!G32="","",Config!G32) -> WS2812B
A33: =IF(Config!B33="","",Config!B33) -> LED01-left-blue_3 | B33: 86 | C33: =IF(Config!D33="","",Config!D33) -> 4 | D33: =IF(Config!F33="","",Config!F33) -> DigitalOut | E33: =IF(Config!G33="","",Config!G33) -> WS2812B
A34: =IF(Config!B34="","",Config!B34) -> LED02 | B34: =IF(Config!C31="","",Config!C31) -> position 1-49 (50-70) | C34: =IF(Config!D34="","",Config!D34) -> 4 | D34: =IF(Config!F34="","",Config!F34) -> DigitalOut | E34: =IF(Config!G34="","",Config!G34) -> WS2812B
A35: =IF(Config!B35="","",Config!B35) -> LED03-strip-down5_1 | B35: 71 | C35: =IF(Config!D35="","",Config!D35) -> 4 | D35: =IF(Config!F35="","",Config!F35) -> DigitalOut | E35: =IF(Config!G35="","",Config!G35) -> WS2812B
A36: =IF(Config!B36="","",Config!B36) -> LED03-strip-down5_2 | B36: 72 | C36: =IF(Config!D36="","",Config!D36) -> 4 | D36: =IF(Config!F36="","",Config!F36) -> DigitalOut | E36: =IF(Config!G36="","",Config!G36) -> WS2812B
A37: =IF(Config!B37="","",Config!B37) -> LED03-strip-down5_3 | B37: 73 | C37: =IF(Config!D37="","",Config!D37) -> 4 | D37: =IF(Config!F37="","",Config!F37) -> DigitalOut | E37: =IF(Config!G37="","",Config!G37) -> WS2812B
A38: =IF(Config!B38="","",Config!B38) -> LED03-strip-down5_4 | B38: 74 | C38: =IF(Config!D38="","",Config!D38) -> 4 | D38: =IF(Config!F38="","",Config!F38) -> DigitalOut | E38: =IF(Config!G38="","",Config!G38) -> WS2812B
A39: =IF(Config!B39="","",Config!B39) -> LED03-strip-down5_5 | B39: 75 | C39: =IF(Config!D39="","",Config!D39) -> 4 | D39: =IF(Config!F39="","",Config!F39) -> DigitalOut | E39: =IF(Config!G39="","",Config!G39) -> WS2812B
A40: =IF(Config!B40="","",Config!B40) -> LED04-right-color_1 | B40: 83 | C40: =IF(Config!D40="","",Config!D40) -> 4 | D40: =IF(Config!F40="","",Config!F40) -> DigitalOut | E40: =IF(Config!G40="","",Config!G40) -> WS2812B
A41: =IF(Config!B41="","",Config!B41) -> LED04-right-color_2 | B41: 82 | C41: =IF(Config!D41="","",Config!D41) -> 4 | D41: =IF(Config!F41="","",Config!F41) -> DigitalOut | E41: =IF(Config!G41="","",Config!G41) -> WS2812B
A42: =IF(Config!B42="","",Config!B42) -> LED04-right-color_3 | B42: 81 | C42: =IF(Config!D42="","",Config!D42) -> 4 | D42: =IF(Config!F42="","",Config!F42) -> DigitalOut | E42: =IF(Config!G42="","",Config!G42) -> WS2812B
A43: =IF(Config!B43="","",Config!B43) -> LED05-metal_1 | B43: 76 | C43: =IF(Config!D43="","",Config!D43) -> 4 | D43: =IF(Config!F43="","",Config!F43) -> DigitalOut | E43: =IF(Config!G43="","",Config!G43) -> WS2812B
A44: =IF(Config!B44="","",Config!B44) -> LED05-metal_2 | B44: 77 | C44: =IF(Config!D44="","",Config!D44) -> 4 | D44: =IF(Config!F44="","",Config!F44) -> DigitalOut | E44: =IF(Config!G44="","",Config!G44) -> WS2812B
A45: =IF(Config!B45="","",Config!B45) -> LED05-metal_3 | B45: 78 | C45: =IF(Config!D45="","",Config!D45) -> 4 | D45: =IF(Config!F45="","",Config!F45) -> DigitalOut | E45: =IF(Config!G45="","",Config!G45) -> WS2812B
A46: =IF(Config!B46="","",Config!B46) -> LED05-metal_4 | B46: 79 | C46: =IF(Config!D46="","",Config!D46) -> 4 | D46: =IF(Config!F46="","",Config!F46) -> DigitalOut | E46: =IF(Config!G46="","",Config!G46) -> WS2812B
A47: =IF(Config!B47="","",Config!B47) -> LED05-metal_5 | B47: 80 | C47: =IF(Config!D47="","",Config!D47) -> 4 | D47: =IF(Config!F47="","",Config!F47) -> DigitalOut | E47: =IF(Config!G47="","",Config!G47) -> WS2812B
A48: =IF(Config!B48="","",Config!B48) -> POT1 | B48: =IF(Config!C48="","",Config!C48) | C48: =IF(Config!D48="","",Config!D48) -> 15 | D48: =IF(Config!F48="","",Config!F48) -> AnalogIn | E48: =IF(Config!G48="","",Config!G48)
A49: =IF(Config!B49="","",Config!B49) -> SW01-metal_1 | C49: =IF(Config!D49="","",Config!D49) -> 40 | D49: =IF(Config!F49="","",Config!F49) -> DigitalIn | E49: =IF(Config!G49="","",Config!G49)
A50: =IF(Config!B50="","",Config!B50) -> SW02-metal_2 | B50: =IF(Config!C50="","",Config!C50) | C50: =IF(Config!D50="","",Config!D50) -> 42 | D50: =IF(Config!F50="","",Config!F50) -> DigitalIn | E50: =IF(Config!G50="","",Config!G50)
A51: =IF(Config!B51="","",Config!B51) -> SW03-metal_3 | B51: =IF(Config!C51="","",Config!C51) | C51: =IF(Config!D51="","",Config!D51) -> 38 | D51: =IF(Config!F51="","",Config!F51) -> DigitalIn | E51: =IF(Config!G51="","",Config!G51)
A52: =IF(Config!B52="","",Config!B52) -> SW04-metal_4 | B52: =IF(Config!C52="","",Config!C52) | C52: =IF(Config!D52="","",Config!D52) -> 36 | D52: =IF(Config!F52="","",Config!F52) -> DigitalIn | E52: =IF(Config!G52="","",Config!G52)
A53: =IF(Config!B53="","",Config!B53) -> SW05-metal_5 | B53: =IF(Config!C53="","",Config!C53) | C53: =IF(Config!D53="","",Config!D53) -> 37 | D53: =IF(Config!F53="","",Config!F53) -> DigitalIn | E53: =IF(Config!G53="","",Config!G53)
...
